<?xml version="1.0" encoding="UTF-8"?>
<testng-results skipped="0" failed="1" ignored="0" total="1" passed="0">
  <reporter-output>
  </reporter-output>
  <suite name="Surefire suite" duration-ms="19993" started-at="2019-01-03T15:28:24Z" finished-at="2019-01-03T15:28:44Z">
    <groups>
    </groups>
    <test name="Surefire test" duration-ms="19993" started-at="2019-01-03T15:28:24Z" finished-at="2019-01-03T15:28:44Z">
      <class name="TestClass">
        <test-method status="PASS" signature="setup()[pri:0, instance:TestClass@5ce81285]" name="setup" is-config="true" duration-ms="5725" started-at="2019-01-03T15:28:24Z" finished-at="2019-01-03T15:28:29Z">
          <reporter-output>
          </reporter-output>
        </test-method> <!-- setup -->
        <test-method status="FAIL" signature="firsttest()[pri:0, instance:TestClass@5ce81285]" name="firsttest" duration-ms="10838" started-at="2019-01-03T15:28:29Z" finished-at="2019-01-03T15:28:40Z">
          <exception class="SupportClasses.NewAssertError">
            <message>
              <![CDATA[Assertion error with message: expected [2] but found [1]]]>
            </message>
            <full-stacktrace>
              <![CDATA[SupportClasses.NewAssertError: Assertion error with message: expected [2] but found [1]
at TestClass.firsttest(TestClass.java:32)
at sun.reflect.NativeMethodAccessorImpl.invoke0(Native Method)
at sun.reflect.NativeMethodAccessorImpl.invoke(NativeMethodAccessorImpl.java:62)
at sun.reflect.DelegatingMethodAccessorImpl.invoke(DelegatingMethodAccessorImpl.java:43)
at java.lang.reflect.Method.invoke(Method.java:498)
at org.testng.internal.MethodInvocationHelper.invokeMethod(MethodInvocationHelper.java:124)
at org.testng.internal.Invoker.invokeMethod(Invoker.java:583)
at org.testng.internal.Invoker.invokeTestMethod(Invoker.java:719)
at org.testng.internal.Invoker.invokeTestMethods(Invoker.java:989)
at org.testng.internal.TestMethodWorker.invokeTestMethods(TestMethodWorker.java:125)
at org.testng.internal.TestMethodWorker.run(TestMethodWorker.java:109)
at org.testng.TestRunner.privateRun(TestRunner.java:648)
at org.testng.TestRunner.run(TestRunner.java:505)
at org.testng.SuiteRunner.runTest(SuiteRunner.java:455)
at org.testng.SuiteRunner.runSequentially(SuiteRunner.java:450)
at org.testng.SuiteRunner.privateRun(SuiteRunner.java:415)
at org.testng.SuiteRunner.run(SuiteRunner.java:364)
at org.testng.SuiteRunnerWorker.runSuite(SuiteRunnerWorker.java:52)
at org.testng.SuiteRunnerWorker.run(SuiteRunnerWorker.java:84)
at org.testng.TestNG.runSuitesSequentially(TestNG.java:1208)
at org.testng.TestNG.runSuitesLocally(TestNG.java:1137)
at org.testng.TestNG.runSuites(TestNG.java:1049)
at org.testng.TestNG.run(TestNG.java:1017)
at org.apache.maven.surefire.testng.TestNGExecutor.run(TestNGExecutor.java:135)
at org.apache.maven.surefire.testng.TestNGDirectoryTestSuite.executeMulti(TestNGDirectoryTestSuite.java:193)
at org.apache.maven.surefire.testng.TestNGDirectoryTestSuite.execute(TestNGDirectoryTestSuite.java:94)
at org.apache.maven.surefire.testng.TestNGProvider.invoke(TestNGProvider.java:146)
at org.apache.maven.surefire.booter.ForkedBooter.invokeProviderInSameClassLoader(ForkedBooter.java:384)
at org.apache.maven.surefire.booter.ForkedBooter.runSuitesInProcess(ForkedBooter.java:345)
at org.apache.maven.surefire.booter.ForkedBooter.execute(ForkedBooter.java:126)
at org.apache.maven.surefire.booter.ForkedBooter.main(ForkedBooter.java:418)
]]>
            </full-stacktrace>
          </exception> <!-- SupportClasses.NewAssertError -->
          <reporter-output>
          </reporter-output>
        </test-method> <!-- firsttest -->
        <test-method status="PASS" signature="teardown()[pri:0, instance:TestClass@5ce81285]" name="teardown" is-config="true" duration-ms="3364" started-at="2019-01-03T15:28:40Z" finished-at="2019-01-03T15:28:44Z">
          <reporter-output>
          </reporter-output>
        </test-method> <!-- teardown -->
      </class> <!-- TestClass -->
    </test> <!-- Surefire test -->
  </suite> <!-- Surefire suite -->
</testng-results>
